Workbook

Sheet Petunjuk
A1: TravelFit — Perhitungan SPK (AHP + TOPSIS) yang Dapat Ditelusuri
A2: Setiap angka turunan di workbook ini adalah formula Excel. Ubah sel input (kuning) dan seluruh hasil ikut berubah.
A4: LEGENDA WARNA
A5: Teks biru + latar kuning | B5: Sel INPUT — boleh diubah (data dummy, profil pengguna, matriks berpasangan AHP)
A6: Teks hitam | B6: Formula perhitungan di sheet yang sama
A7: Teks hijau | B7: Formula yang menautkan ke sheet lain (link)
A8: Latar hijau muda | B8: Alternatif terbaik / hasil akhir
A10: ALUR PERHITUNGAN (urutan sheet)
A11: 1. Profil_User | B11: Preferensi pengguna: kota asal (koordinat), budget, wilayah, kategori minat, hobi
A12: 2. Data_Alternatif | B12: 10 destinasi dummy + atribut turunan C3 (haversine), C4 (fasilitas), C5 (kategori), C6 (Jaccard), dan filter kelayakan
A13: 3. Kriteria | B13: Definisi C1–C6, jenis Cost/Benefit
A14: 4. AHP_Bobot | B14: Matriks perbandingan berpasangan → normalisasi → bobot → λmax, CI, RI, CR (< 0,1 = konsisten)
A15: 5. Matriks_Keputusan | B15: Matriks X (10 alternatif × 6 kriteria) yang menjadi input TOPSIS dan SAW
A16: 6. TOPSIS | B16: Normalisasi vektor → terbobot → A+ / A− → D+ / D− → Vi → peringkat → alternatif terbaik → kedekatan per kriteria (explainability)
A17: 7. SAW_Pembanding | B17: Ranking SAW dengan bobot yang sama + Spearman ρ terhadap TOPSIS (validasi, bukan penentu rekomendasi)
A18: 8. Hasil | B18: Ranking akhir terurut, alternatif terbaik, dan alasan per kriteria
A20: KONVENSI YANG WAJIB DIIKUTI APLIKASI WEB (agar hasil 100% identik)
A21: C3 Jarak | B21: Haversine, R = 6371 km, dari koordinat kota asal ke koordinat destinasi
A22: C4 Fasilitas | B22: Jumlah fasilitas tersedia ÷ jumlah jenis fasilitas yang dinilai (5)
A23: C5 Kategori | B23: 1 jika = kategori utama; 0,5 jika = kategori sekunder; 0 selain itu
A24: C6 Hobi | B24: Jaccard = |hobi ∩ tag| ÷ |hobi ∪ tag|; 0 jika gabungan kosong
A25: Filter keras | B25: Hanya budget (harga ≤ budget) dan wilayah (provinsi = wilayah). Kategori & hobi TIDAK difilter
A26: AHP bobot | B26: w_i = rata-rata baris dari matriks yang dinormalisasi per kolom (Σ kolom = 1)
A27: AHP λmax | B27: λmax = rata-rata dari (A·w)_i ÷ w_i ; CI = (λmax − n)/(n − 1) ; CR = CI/RI, RI(n=6) = 1,24 (Saaty)
A28: TOPSIS normalisasi | B28: r_ij = x_ij ÷ √Σ_i x_ij² (normalisasi vektor)
A29: TOPSIS ideal | B29: Benefit: A+ = max v, A− = min v ; Cost: A+ = min v, A− = max v
A30: TOPSIS jarak | B30: Euclidean: D± = √Σ_j (v_ij − A±_j)² ; Vi = D− ÷ (D+ + D−)
A31: Peringkat | B31: Vi terbesar = peringkat 1 (RANK menurun)
A32: Explainability | B32: c_ij = 1 − |v_ij − A+_j| ÷ |A+_j − A−_j| (1 = tepat di ideal, 0 = tepat di anti-ideal)
... A34: Spearman | B34: ρ = 1 − 6Σd² ÷ (n(n² − 1)), d = peringkat TOPSIS − peringkat SAW
A36: CATATAN
A37: Data | B37: Seluruh angka destinasi adalah DUMMY/ilustrasi (nama tempat nyata, nilai fiktif) — bukan hasil pengumpulan data
A38: K-Means | B38: Tidak dihitung di workbook ini; label cluster hanya bersifat keterangan pada tahap Deployment
A39: Presisi | B39: Excel/aplikasi web sama-sama memakai floating-point 64-bit; hasil identik sampai pembulatan 4 desimal

Sheet Profil_User
A1: 1. Profil Preferensi Pengguna
A2: Sel kuning = input. Semua sheet lain merujuk ke sini.
A4: Parameter | B4: Nilai | C4: Keterangan
A5: Kota asal | B5: Bandung | C5: Nama kota asal pengguna
A6: Latitude kota asal | B6: -6.9175 | C6: Derajat desimal (untuk haversine C3)
A7: Longitude kota asal | B7: 107.6191 | C7: Derajat desimal
A8: Budget maksimal (Rp) | B8: 250000 | C8: Filter keras: harga tiket ≤ budget
A9: Wilayah tujuan (Provinsi) | B9: Jawa Barat | C9: Filter keras: provinsi destinasi = wilayah
A10: Kategori utama | B10: Alam | C10: Skor C5 = 1
A11: Kategori sekunder | B11: Budaya | C11: Skor C5 = 0,5
A12: Profil prioritas (AHP) | B12: Seimbang | C12: Nama profil untuk matriks berpasangan di sheet AHP_Bobot
A14: Hobi pengguna (1 = ya, 0 = tidak)
A15: Tag aktivitas | B15: Hiking | C15: Fotografi | D15: Kuliner | E15: Air/Pantai | F15: Sejarah | G15: Keluarga
A16: Hobi pengguna | B16: 1 | C16: 1 | D16: 1 | E16: 0 | F16: 0 | G16: 0
A17: Jumlah hobi dipilih | B17: =SUM(B16:G16) -> 3

Sheet Data_Alternatif
A1: 2. Data Alternatif (10 destinasi dummy) + Atribut Turunan
A2: Kolom A–S = data mentah (input). Kolom T–X = formula. Nama tempat nyata, seluruh nilai fiktif untuk ilustrasi.
I4: Fasilitas (1 = ada) | N4: Tag aktivitas (1 = ada) | T4: Atribut turunan (formula) & filter
A5: ID | B5: Nama Destinasi | C5: Provinsi | D5: Kategori | E5: Harga Tiket (Rp) | F5: Rating (1–5) | G5: Latitude | H5: Longitude | I5: Toilet | J5: Parkir | K5: Warung | L5: Mushola | M5: Penginapan | N5: Hiking | O5: Fotografi | P5: Kuliner | Q5: Air/Pantai | R5: Sejarah | S5: Keluarga | T5: C3 Jarak (km) | U5: C4 Skor Fasilitas | V5: C5 Skor Kategori | W5: C6 Jaccard Hobi | X5: Lolos Filter?
A6: A1 | B6: Kawah Putih Ciwidey | C6: Jawa Barat | D6: Alam | E6: 81000 | F6: 4.6 | G6: -7.1662 | H6: 107.4022 | I6: 1 | J6: 1 | K6: 1 | L6: 1 | M6: 0 | N6: 1 | O6: 1 | P6: 0 | Q6: 0 | R6: 0 | S6: 1 | T6: =2*6371*ASIN(SQRT(SIN(RADIANS(G6-Profil_User!$B$6)/2)^2+COS(RADIANS(Profil_User!$B$6))*COS(RADIANS(G6))*SIN(RADIANS(H6-Profil_User!$B$7)/2)^2)) -> 36.574538 | U6: =SUM(I6:M6)/COUNTA($I$5:$M$5) -> 0.8 | V6: =IF(D6=Profil_User!$B$10,1,IF(D6=Profil_User!$B$11,0.5,0)) -> 1 | W6: =IFERROR(SUMPRODUCT(N6:S6,Profil_User!$B$16:$G$16)/(SUM(N6:S6)+SUM(Profil_User!$B$16:$G$16)-SUMPRODUCT(N6:S6,Profil_User!$B$16:$G$16)),0) -> 0.5 | X6: =IF(AND(E6<=Profil_User!$B$8,C6=Profil_User!$B$9),"Lolos","Tidak lolos") -> Lolos
A7: A2 | B7: Gunung Tangkuban Perahu | C7: Jawa Barat | D7: Alam | E7: 30000 | F7: 4.4 | G7: -6.7597 | H7: 107.6097 | I7: 1 | J7: 1 | K7: 1 | L7: 1 | M7: 0 | N7: 1 | O7: 1 | P7: 0 | Q7: 0 | R7: 0 | S7: 1 | T7: =2*6371*ASIN(SQRT(SIN(RADIANS(G7-Profil_User!$B$6)/2)^2+COS(RADIANS(Profil_User!$B$6))*COS(RADIANS(G7))*SIN(RADIANS(H7-Profil_User!$B$7)/2)^2)) -> 17.577223 | U7: =SUM(I7:M7)/COUNTA($I$5:$M$5) -> 0.8 | V7: =IF(D7=Profil_User!$B$10,1,IF(D7=Profil_User!$B$11,0.5,0)) -> 1 | W7: =IFERROR(SUMPRODUCT(N7:S7,Profil_User!$B$16:$G$16)/(SUM(N7:S7)+SUM(Profil_User!$B$16:$G$16)-SUMPRODUCT(N7:S7,Profil_User!$B$16:$G$16)),0) -> 0.5 | X7: =IF(AND(E7<=Profil_User!$B$8,C7=Profil_User!$B$9),"Lolos","Tidak lolos") -> Lolos
A8: A3 | B8: Saung Angklung Udjo | C8: Jawa Barat | D8: Budaya | E8: 75000 | F8: 4.7 | G8: -6.8977 | H8: 107.6553 | I8: 1 | J8: 1 | K8: 1 | L8: 1 | M8: 0 | N8: 0 | O8: 1 | P8: 0 | Q8: 0 | R8: 1 | S8: 1 | T8: =2*6371*ASIN(SQRT(SIN(RADIANS(G8-Profil_User!$B$6)/2)^2+COS(RADIANS(Profil_User!$B$6))*COS(RADIANS(G8))*SIN(RADIANS(H8-Profil_User!$B$7)/2)^2)) -> 4.5624148 | U8: =SUM(I8:M8)/COUNTA($I$5:$M$5) -> 0.8 | V8: =IF(D8=Profil_User!$B$10,1,IF(D8=Profil_User!$B$11,0.5,0)) -> 0.5 | W8: =IFERROR(SUMPRODUCT(N8:S8,Profil_User!$B$16:$G$16)/(SUM(N8:S8)+SUM(Profil_User!$B$16:$G$16)-SUMPRODUCT(N8:S8,Profil_User!$B$16:$G$16)),0) -> 0.2 | X8: =IF(AND(E8<=Profil_User!$B$8,C8=Profil_User!$B$9),"Lolos","Tidak lolos") -> Lolos
A9: A4 | B9: Farmhouse Lembang | C9: Jawa Barat | D9: Hiburan | E9: 30000 | F9: 4.3 | G9: -6.833 | H9: 107.6027 | I9: 1 | J9: 1 | K9: 1 | L9: 1 | M9: 0 | N9: 0 | O9: 1 | P9: 1 | Q9: 0 | R9: 0 | S9: 1 | T9: =2*6371*ASIN(SQRT(SIN(RADIANS(G9-Profil_User!$B$6)/2)^2+COS(RADIANS(Profil_User!$B$6))*COS(RADIANS(G9))*SIN(RADIANS(H9-Profil_User!$B$7)/2)^2)) -> 9.5688101 | U9: =SUM(I9:M9)/COUNTA($I$5:$M$5) -> 0.8 | V9: =IF(D9=Profil_User!$B$10,1,IF(D9=Profil_User!$B$11,0.5,0)) -> 0 | W9: =IFERROR(SUMPRODUCT(N9:S9,Profil_User!$B$16:$G$16)/(SUM(N9:S9)+SUM(Profil_User!$B$16:$G$16)-SUMPRODUCT(N9:S9,Profil_User!$B$16:$G$16)),0) -> 0.5 | X9: =IF(AND(E9<=Profil_User!$B$8,C9=Profil_User!$B$9),"Lolos","Tidak lolos") -> Lolos
A10: A5 | B10: Trans Studio Bandung | C10: Jawa Barat | D10: Hiburan | E10: 200000 | F10: 4.5 | G10: -6.9258 | H10: 107.6366 | I10: 1 | J10: 1 | K10: 1 | L10: 1 | M10: 1 | N10: 0 | O10: 0 | P10: 1 | Q10: 0 | R10: 0 | S10: 1 | T10: =2*6371*ASIN(SQRT(SIN(RADIANS(G10-Profil_User!$B$6)/2)^2+COS(RADIANS(Profil_User!$B$6))*COS(RADIANS(G10))*SIN(RADIANS(H10-Profil_User!$B$7)/2)^2)) -> 2.1408772 | U10: =SUM(I10:M10)/COUNTA($I$5:$M$5) -> 1 | V10: =IF(D10=Profil_User!$B$10,1,IF(D10=Profil_User!$B$11,0.5,0)) -> 0 | W10: =IFERROR(SUMPRODUCT(N10:S10,Profil_User!$B$16:$G$16)/(SUM(N10:S10)+SUM(Profil_User!$B$16:$G$16)-SUMPRODUCT(N10:S10,Profil_User!$B$16:$G$16)),0) -> 0.25 | X10: =IF(AND(E10<=Profil_User!$B$8,C10=Profil_User!$B$9),"Lolos","Tidak lolos") -> Lolos
A11: A6 | B11: Pantai Pangandaran | C11: Jawa Barat | D11: Alam | E11: 15000 | F11: 4.2 | G11: -7.695 | H11: 108.655 | I11: 1 | J11: 1 | K11: 1 | L11: 1 | M11: 1 | N11: 0 | O11: 1 | P11: 1 | Q11: 1 | R11: 0 | S11: 1 | T11: =2*6371*ASIN(SQRT(SIN(RADIANS(G11-Profil_User!$B$6)/2)^2+COS(RADIANS(Profil_User!$B$6))*COS(RADIANS(G11))*SIN(RADIANS(H11-Profil_User!$B$7)/2)^2)) -> 143.27425 | U11: =SUM(I11:M11)/COUNTA($I$5:$M$5) -> 1 | V11: =IF(D11=Profil_User!$B$10,1,IF(D11=Profil_User!$B$11,0.5,0)) -> 1 | W11: =IFERROR(SUMPRODUCT(N11:S11,Profil_User!$B$16:$G$16)/(SUM(N11:S11)+SUM(Profil_User!$B$16:$G$16)-SUMPRODUCT(N11:S11,Profil_User!$B$16:$G$16)),0) -> 0.4 | X11: =IF(AND(E11<=Profil_User!$B$8,C11=Profil_User!$B$9),"Lolos","Tidak lolos") -> Lolos
A12: A7 | B12: Museum Geologi Bandung | C12: Jawa Barat | D12: Budaya | E12: 5000 | F12: 4.5 | G12: -6.9007 | H12: 107.6215 | I12: 1 | J12: 1 | K12: 0 | L12: 1 | M12: 0 | N12: 0 | O12: 0 | P12: 0 | Q12: 0 | R12: 1 | S12: 1 | T12: =2*6371*ASIN(SQRT(SIN(RADIANS(G12-Profil_User!$B$6)/2)^2+COS(RADIANS(Profil_User!$B$6))*COS(RADIANS(G12))*SIN(RADIANS(H12-Profil_User!$B$7)/2)^2)) -> 1.8867674 | U12: =SUM(I12:M12)/COUNTA($I$5:$M$5) -> 0.6 | V12: =IF(D12=Profil_User!$B$10,1,IF(D12=Profil_User!$B$11,0.5,0)) -> 0.5 | W12: =IFERROR(SUMPRODUCT(N12:S12,Profil_User!$B$16:$G$16)/(SUM(N12:S12)+SUM(Profil_User!$B$16:$G$16)-SUMPRODUCT(N12:S12,Profil_User!$B$16:$G$16)),0) -> 0 | X12: =IF(AND(E12<=Profil_User!$B$8,C12=Profil_User!$B$9),"Lolos","Tidak lolos") -> Lolos
A13: A8 | B13: Dusun Bambu Lembang | C13: Jawa Barat | D13: Kuliner | E13: 25000 | F13: 4.4 | G13: -6.796 | H13: 107.575 | I13: 1 | J13: 1 | K13: 1 | L13: 1 | M13: 1 | N13: 0 | O13: 1 | P13: 1 | Q13: 0 | R13: 0 | S13: 1 | T13: =2*6371*ASIN(SQRT(SIN(RADIANS(G13-Profil_User!$B$6)/2)^2+COS(RADIANS(Profil_User!$B$6))*COS(RADIANS(G13))*SIN(RADIANS(H13-Profil_User!$B$7)/2)^2)) -> 14.36066 | U13: =SUM(I13:M13)/COUNTA($I$5:$M$5) -> 1 | V13: =IF(D13=Profil_User!$B$10,1,IF(D13=Profil_User!$B$11,0.5,0)) -> 0 | W13: =IFERROR(SUMPRODUCT(N13:S13,Profil_User!$B$16:$G$16)/(SUM(N13:S13)+SUM(Profil_User!$B$16:$G$16)-SUMPRODUCT(N13:S13,Profil_User!$B$16:$G$16)),0) -> 0.5 | X13: =IF(AND(E13<=Profil_User!$B$8,C13=Profil_User!$B$9),"Lolos","Tidak lolos") -> Lolos
A14: A9 | B14: Situ Patenggang | C14: Jawa Barat | D14: Alam | E14: 20000 | F14: 4.3 | G14: -7.165 | H14: 107.36 | I14: 1 | J14: 1 | K14: 1 | L14: 0 | M14: 0 | N14: 1 | O14: 1 | P14: 0 | Q14: 1 | R14: 0 | S14: 1 | T14: =2*6371*ASIN(SQRT(SIN(RADIANS(G14-Profil_User!$B$6)/2)^2+COS(RADIANS(Profil_User!$B$6))*COS(RADIANS(G14))*SIN(RADIANS(H14-Profil_User!$B$7)/2)^2)) -> 39.685866 | U14: =SUM(I14:M14)/COUNTA($I$5:$M$5) -> 0.6 | V14: =IF(D14=Profil_User!$B$10,1,IF(D14=Profil_User!$B$11,0.5,0)) -> 1 | W14: =IFERROR(SUMPRODUCT(N14:S14,Profil_User!$B$16:$G$16)/(SUM(N14:S14)+SUM(Profil_User!$B$16:$G$16)-SUMPRODUCT(N14:S14,Profil_User!$B$16:$G$16)),0) -> 0.4 | X14: =IF(AND(E14<=Profil_User!$B$8,C14=Profil_User!$B$9),"Lolos","Tidak lolos") -> Lolos
A15: A10 | B15: Masjid Raya Al Jabbar | C15: Jawa Barat | D15: Religi | E15: 5000 | F15: 4.1 | G15: -6.945 | H15: 107.69 | I15: 1 | J15: 1 | K15: 1 | L15: 1 | M15: 0 | N15: 0 | O15: 1 | P15: 0 | Q15: 0 | R15: 1 | S15: 1 | T15: =2*6371*ASIN(SQRT(SIN(RADIANS(G15-Profil_User!$B$6)/2)^2+COS(RADIANS(Profil_User!$B$6))*COS(RADIANS(G15))*SIN(RADIANS(H15-Profil_User!$B$7)/2)^2)) -> 8.4022857 | U15: =SUM(I15:M15)/COUNTA($I$5:$M$5) -> 0.8 | V15: =IF(D15=Profil_User!$B$10,1,IF(D15=Profil_User!$B$11,0.5,0)) -> 0 | W15: =IFERROR(SUMPRODUCT(N15:S15,Profil_User!$B$16:$G$16)/(SUM(N15:S15)+SUM(Profil_User!$B$16:$G$16)-SUMPRODUCT(N15:S15,Profil_User!$B$16:$G$16)),0) -> 0.2 | X15: =IF(AND(E15<=Profil_User!$B$8,C15=Profil_User!$B$9),"Lolos","Tidak lolos") -> Lolos
A17: Keterangan formula:
A18: C3 = 2·6371·asin(√(sin²(Δlat/2) + cos(lat1)·cos(lat2)·sin²(Δlon/2))) — haversine dari kota asal (Profil_User) ke destinasi.
A19: C4 = jumlah fasilitas yang ada ÷ 5 jenis fasilitas yang dinilai.
A20: C5 = 1 (kategori utama) / 0,5 (kategori sekunder) / 0 (lainnya) — dibandingkan dengan Profil_User.
A21: C6 = Jaccard: |tag ∩ hobi| ÷ |tag ∪ hobi|; SUMPRODUCT menghitung irisan, SUM + SUM − irisan menghitung gabungan.
A22: Lolos Filter = harga ≤ budget DAN provinsi = wilayah tujuan. Hanya alternatif yang lolos yang dibawa ke Matriks_Keputusan (pada contoh ini semuanya lolos).

Sheet Kriteria
A1: 3. Kriteria Keputusan (C1–C6)
A4: Kode | B4: Kriteria | C4: Jenis | D4: Sumber nilai (Data_Alternatif) | E4: Penjelasan
A5: C1 | B5: Harga Tiket (Rp) | C5: Cost | D5: Kolom E (Harga Tiket) | E5: Semakin murah semakin baik; dibatasi budget sebagai filter keras
A6: C2 | B6: Rating Pengunjung | C6: Benefit | D6: Kolom F (Rating) | E6: Penilaian rata-rata pengunjung, skala 1–5
A7: C3 | B7: Jarak (km) | C7: Cost | D7: Kolom T (haversine) | E7: Jarak garis lurus dari kota asal pengguna; semakin dekat semakin baik
A8: C4 | B8: Skor Fasilitas | C8: Benefit | D8: Kolom U (fasilitas/5) | E8: Ketersediaan fasilitas pendukung (toilet, parkir, warung, mushola, penginapan)
A9: C5 | B9: Skor Kategori | C9: Benefit | D9: Kolom V (1 / 0,5 / 0) | E9: Kecocokan kategori destinasi dengan minat pengguna (bertingkat, bukan filter)
A10: C6 | B10: Skor Hobi (Jaccard) | C10: Benefit | D10: Kolom W (Jaccard) | E10: Kemiripan tag aktivitas destinasi dengan hobi pengguna (Jaccard Similarity)
A12: Jenis kriteria (Cost/Benefit) adalah input: TOPSIS dan SAW membaca kolom C untuk menentukan arah solusi ideal dan rumus normalisasi.

Sheet AHP_Bobot
A1: 4. AHP — Pembobotan Kriteria
A2: Isi hanya segitiga atas (kuning). Segitiga bawah otomatis = 1/kebalikannya (aksioma resiprokal AHP).
A3: Profil prioritas: | B3: =Profil_User!$B$12 -> Seimbang
A4: Skala Saaty: 1 = sama penting, 3 = sedikit lebih penting, 5 = lebih penting, 7 = sangat lebih penting, 9 = mutlak; 2,4,6,8 = nilai antara.
A5: 4a. Matriks perbandingan berpasangan A (baris i dibanding kolom j)
A6: A | B6: C1 | C6: C2 | D6: C3 | E6: C4 | F6: C5 | G6: C6 | J6: n | K6: RI
A7: C1 Harga Tiket (Rp) | B7: 1 | C7: 1 | D7: 2 | E7: 3 | F7: 2 | G7: 2 | J7: 1 | K7: 0
A8: C2 Rating Pengunjung | B8: =1/C7 -> 1 | C8: 1 | D8: 1 | E8: 2 | F8: 1 | G8: 1 | J8: 2 | K8: 0
A9: C3 Jarak (km) | B9: =1/D7 -> 0.5 | C9: =1/D8 -> 1 | D9: 1 | E9: 2 | F9: 1 | G9: 1 | J9: 3 | K9: 0.58
A10: C4 Skor Fasilitas | B10: =1/E7 -> 0.33333333 | C10: =1/E8 -> 0.5 | D10: =1/E9 -> 0.5 | E10: 1 | F10: 0.5 | G10: 0.5 | J10: 4 | K10: 0.9
A11: C5 Skor Kategori | B11: =1/F7 -> 0.5 | C11: =1/F8 -> 1 | D11: =1/F9 -> 1 | E11: =1/F10 -> 2 | F11: 1 | G11: 1 | J11: 5 | K11: 1.12
A12: C6 Skor Hobi (Jaccard) | B12: =1/G7 -> 0.5 | C12: =1/G8 -> 1 | D12: =1/G9 -> 1 | E12: =1/G10 -> 2 | F12: =1/G11 -> 1 | G12: 1 | J12: 6 | K12: 1.24
A13: Jumlah kolom Σ_i a_ij | B13: =SUM(B7:B12) -> 3.8333333 | C13: =SUM(C7:C12) -> 5.5 | D13: =SUM(D7:D12) -> 6.5 | E13: =SUM(E7:E12) -> 12 | F13: =SUM(F7:F12) -> 6.5 | G13: =SUM(G7:G12) -> 6.5 | J13: 7 | K13: 1.32
J14: 8 | K14: 1.41
A15: 4b. Matriks ternormalisasi a'_ij = a_ij ÷ Σ_i a_ij → bobot w_i = rata-rata baris | J15: 9 | K15: 1.45
A16: A' | B16: C1 | C16: C2 | D16: C3 | E16: C4 | F16: C5 | G16: C6 | H16: Bobot w_i | J16: 10 | K16: 1.49
A17: C1 Harga Tiket (Rp) | B17: =B7/B$13 -> 0.26086957 | C17: =C7/C$13 -> 0.18181818 | D17: =D7/D$13 -> 0.30769231 | E17: =E7/E$13 -> 0.25 | F17: =F7/F$13 -> 0.30769231 | G17: =G7/G$13 -> 0.30769231 | H17: =AVERAGE(B17:G17) -> 0.26929411 | J17: Sumber RI: Saaty (1980)
A18: C2 Rating Pengunjung | B18: =B8/B$13 -> 0.26086957 | C18: =C8/C$13 -> 0.18181818 | D18: =D8/D$13 -> 0.15384615 | E18: =E8/E$13 -> 0.16666667 | F18: =F8/F$13 -> 0.15384615 | G18: =G8/G$13 -> 0.15384615 | H18: =AVERAGE(B18:G18) -> 0.17848215
A19: C3 Jarak (km) | B19: =B9/B$13 -> 0.13043478 | C19: =C9/C$13 -> 0.18181818 | D19: =D9/D$13 -> 0.15384615 | E19: =E9/E$13 -> 0.16666667 | F19: =F9/F$13 -> 0.15384615 | G19: =G9/G$13 -> 0.15384615 | H19: =AVERAGE(B19:G19) -> 0.15674302
A20: C4 Skor Fasilitas | B20: =B10/B$13 -> 0.086956522 | C20: =C10/C$13 -> 0.090909091 | D20: =D10/D$13 -> 0.076923077 | E20: =E10/E$13 -> 0.083333333 | F20: =F10/F$13 -> 0.076923077 | G20: =G10/G$13 -> 0.076923077 | H20: =AVERAGE(B20:G20) -> 0.081994696
A21: C5 Skor Kategori | B21: =B11/B$13 -> 0.13043478 | C21: =C11/C$13 -> 0.18181818 | D21: =D11/D$13 -> 0.15384615 | E21: =E11/E$13 -> 0.16666667 | F21: =F11/F$13 -> 0.15384615 | G21: =G11/G$13 -> 0.15384615 | H21: =AVERAGE(B21:G21) -> 0.15674302
A22: C6 Skor Hobi (Jaccard) | B22: =B12/B$13 -> 0.13043478 | C22: =C12/C$13 -> 0.18181818 | D22: =D12/D$13 -> 0.15384615 | E22: =E12/E$13 -> 0.16666667 | F22: =F12/F$13 -> 0.15384615 | G22: =G12/G$13 -> 0.15384615 | H22: =AVERAGE(B22:G22) -> 0.15674302
A23: Σ bobot (harus = 1) | H23: =SUM(H17:H22) -> 1
A25: 4c. Uji konsistensi (Consistency Ratio)
A26: w (sebagai baris) | B26: =$H$17 -> 0.26929411 | C26: =$H$18 -> 0.17848215 | D26: =$H$19 -> 0.15674302 | E26: =$H$20 -> 0.081994696 | F26: =$H$21 -> 0.15674302 | G26: =$H$22 -> 0.15674302
A27: Kriteria | B27: w_i | C27: (A·w)_i = Σ_j a_ij·w_j | D27: λ_i = (A·w)_i ÷ w_i
A28: C1 | B28: =H17 -> 0.26929411 | C28: =SUMPRODUCT(B7:G7,$B$26:$G$26) -> 1.6342184 | D28: =C28/B28 -> 6.0685264
A29: C2 | B29: =H18 -> 0.17848215 | C29: =SUMPRODUCT(B8:G8,$B$26:$G$26) -> 1.0819947 | D29: =C29/B29 -> 6.0622013
A30: C3 | B30: =H19 -> 0.15674302 | C30: =SUMPRODUCT(B9:G9,$B$26:$G$26) -> 0.94734764 | D30: =C30/B30 -> 6.0439544
A31: C4 | B31: =H20 -> 0.081994696 | C31: =SUMPRODUCT(B10:G10,$B$26:$G$26) -> 0.496115 | D31: =C31/B31 -> 6.0505742
A32: C5 | B32: =H21 -> 0.15674302 | C32: =SUMPRODUCT(B11:G11,$B$26:$G$26) -> 0.94734764 | D32: =C32/B32 -> 6.0439544
A33: C6 | B33: =H22 -> 0.15674302 | C33: =SUMPRODUCT(B12:G12,$B$26:$G$26) -> 0.94734764 | D33: =C33/B33 -> 6.0439544
A34: λmax = rata-rata λ_i | D34: =AVERAGE(D28:D33) -> 6.0521942
A35: n (jumlah kriteria) | D35: =COUNTA(A28:A33) -> 6
A36: CI = (λmax − n) ÷ (n − 1) | D36: =(D34-D35)/(D35-1) -> 0.010438841
A37: RI (Random Index, Saaty) untuk n | D37: =INDEX($K$7:$K$16,D35) -> 1.24
A38: CR = CI ÷ RI | D38: =D36/D37 -> 0.0084184201
A39: Status | D39: =IF(D38<0.1,"KONSISTEN (CR < 0,1) — bobot dapat dipakai","TIDAK KONSISTEN — perbaiki matriks") -> KONSISTEN (CR < 0,1) — bobot dapat dipakai

Sheet Matriks_Keputusan
A1: 5. Matriks Keputusan X (alternatif × kriteria)
A2: Semua nilai adalah link ke Data_Alternatif, jenis ke Kriteria, bobot ke AHP_Bobot.
A4: ID | B4: Destinasi | C4: C1 Harga Tiket (Rp) | D4: C2 Rating Pengunjung | E4: C3 Jarak (km) | F4: C4 Skor Fasilitas | G4: C5 Skor Kategori | H4: C6 Skor Hobi (Jaccard)
A5: Jenis | C5: =Kriteria!$C$5 -> Cost | D5: =Kriteria!$C$6 -> Benefit | E5: =Kriteria!$C$7 -> Cost | F5: =Kriteria!$C$8 -> Benefit | G5: =Kriteria!$C$9 -> Benefit | H5: =Kriteria!$C$10 -> Benefit
A6: Bobot w_j (AHP) | C6: =AHP_Bobot!$H$17 -> 0.26929411 | D6: =AHP_Bobot!$H$18 -> 0.17848215 | E6: =AHP_Bobot!$H$19 -> 0.15674302 | F6: =AHP_Bobot!$H$20 -> 0.081994696 | G6: =AHP_Bobot!$H$21 -> 0.15674302 | H6: =AHP_Bobot!$H$22 -> 0.15674302
A7: =Data_Alternatif!A6 -> A1 | B7: =Data_Alternatif!B6 -> Kawah Putih Ciwidey | C7: =Data_Alternatif!E6 -> 81000 | D7: =Data_Alternatif!F6 -> 4.6 | E7: =Data_Alternatif!T6 -> 36.574538 | F7: =Data_Alternatif!U6 -> 0.8 | G7: =Data_Alternatif!V6 -> 1 | H7: =Data_Alternatif!W6 -> 0.5
A8: =Data_Alternatif!A7 -> A2 | B8: =Data_Alternatif!B7 -> Gunung Tangkuban Perahu | C8: =Data_Alternatif!E7 -> 30000 | D8: =Data_Alternatif!F7 -> 4.4 | E8: =Data_Alternatif!T7 -> 17.577223 | F8: =Data_Alternatif!U7 -> 0.8 | G8: =Data_Alternatif!V7 -> 1 | H8: =Data_Alternatif!W7 -> 0.5
A9: =Data_Alternatif!A8 -> A3 | B9: =Data_Alternatif!B8 -> Saung Angklung Udjo | C9: =Data_Alternatif!E8 -> 75000 | D9: =Data_Alternatif!F8 -> 4.7 | E9: =Data_Alternatif!T8 -> 4.5624148 | F9: =Data_Alternatif!U8 -> 0.8 | G9: =Data_Alternatif!V8 -> 0.5 | H9: =Data_Alternatif!W8 -> 0.2
A10: =Data_Alternatif!A9 -> A4 | B10: =Data_Alternatif!B9 -> Farmhouse Lembang | C10: =Data_Alternatif!E9 -> 30000 | D10: =Data_Alternatif!F9 -> 4.3 | E10: =Data_Alternatif!T9 -> 9.5688101 | F10: =Data_Alternatif!U9 -> 0.8 | G10: =Data_Alternatif!V9 -> 0 | H10: =Data_Alternatif!W9 -> 0.5
A11: =Data_Alternatif!A10 -> A5 | B11: =Data_Alternatif!B10 -> Trans Studio Bandung | C11: =Data_Alternatif!E10 -> 200000 | D11: =Data_Alternatif!F10 -> 4.5 | E11: =Data_Alternatif!T10 -> 2.1408772 | F11: =Data_Alternatif!U10 -> 1 | G11: =Data_Alternatif!V10 -> 0 | H11: =Data_Alternatif!W10 -> 0.25
A12: =Data_Alternatif!A11 -> A6 | B12: =Data_Alternatif!B11 -> Pantai Pangandaran | C12: =Data_Alternatif!E11 -> 15000 | D12: =Data_Alternatif!F11 -> 4.2 | E12: =Data_Alternatif!T11 -> 143.27425 | F12: =Data_Alternatif!U11 -> 1 | G12: =Data_Alternatif!V11 -> 1 | H12: =Data_Alternatif!W11 -> 0.4
A13: =Data_Alternatif!A12 -> A7 | B13: =Data_Alternatif!B12 -> Museum Geologi Bandung | C13: =Data_Alternatif!E12 -> 5000 | D13: =Data_Alternatif!F12 -> 4.5 | E13: =Data_Alternatif!T12 -> 1.8867674 | F13: =Data_Alternatif!U12 -> 0.6 | G13: =Data_Alternatif!V12 -> 0.5 | H13: =Data_Alternatif!W12 -> 0
A14: =Data_Alternatif!A13 -> A8 | B14: =Data_Alternatif!B13 -> Dusun Bambu Lembang | C14: =Data_Alternatif!E13 -> 25000 | D14: =Data_Alternatif!F13 -> 4.4 | E14: =Data_Alternatif!T13 -> 14.36066 | F14: =Data_Alternatif!U13 -> 1 | G14: =Data_Alternatif!V13 -> 0 | H14: =Data_Alternatif!W13 -> 0.5
A15: =Data_Alternatif!A14 -> A9 | B15: =Data_Alternatif!B14 -> Situ Patenggang | C15: =Data_Alternatif!E14 -> 20000 | D15: =Data_Alternatif!F14 -> 4.3 | E15: =Data_Alternatif!T14 -> 39.685866 | F15: =Data_Alternatif!U14 -> 0.6 | G15: =Data_Alternatif!V14 -> 1 | H15: =Data_Alternatif!W14 -> 0.4
A16: =Data_Alternatif!A15 -> A10 | B16: =Data_Alternatif!B15 -> Masjid Raya Al Jabbar | C16: =Data_Alternatif!E15 -> 5000 | D16: =Data_Alternatif!F15 -> 4.1 | E16: =Data_Alternatif!T15 -> 8.4022857 | F16: =Data_Alternatif!U15 -> 0.8 | G16: =Data_Alternatif!V15 -> 0 | H16: =Data_Alternatif!W15 -> 0.2
A18: Catatan: bila ada alternatif yang 'Tidak lolos' filter di Data_Alternatif, hapus barisnya dari matriks ini sebelum TOPSIS (pada contoh, 10 alternatif lolos semua).

Sheet TOPSIS
A1: 6. TOPSIS — Perankingan Alternatif
A2: Setiap langkah ditampilkan sebagai tabel terpisah; sel abu-abu = link, hitam = formula.
A3: Langkah 1 — Matriks keputusan X (link dari Matriks_Keputusan)
A4: ID | B4: Destinasi | C4: C1 | D4: C2 | E4: C3 | F4: C4 | G4: C5 | H4: C6
A5: =Matriks_Keputusan!A7 -> A1 | B5: =Matriks_Keputusan!B7 -> Kawah Putih Ciwidey | C5: =Matriks_Keputusan!C7 -> 81000 | D5: =Matriks_Keputusan!D7 -> 4.6 | E5: =Matriks_Keputusan!E7 -> 36.574538 | F5: =Matriks_Keputusan!F7 -> 0.8 | G5: =Matriks_Keputusan!G7 -> 1 | H5: =Matriks_Keputusan!H7 -> 0.5
A6: =Matriks_Keputusan!A8 -> A2 | B6: =Matriks_Keputusan!B8 -> Gunung Tangkuban Perahu | C6: =Matriks_Keputusan!C8 -> 30000 | D6: =Matriks_Keputusan!D8 -> 4.4 | E6: =Matriks_Keputusan!E8 -> 17.577223 | F6: =Matriks_Keputusan!F8 -> 0.8 | G6: =Matriks_Keputusan!G8 -> 1 | H6: =Matriks_Keputusan!H8 -> 0.5
A7: =Matriks_Keputusan!A9 -> A3 | B7: =Matriks_Keputusan!B9 -> Saung Angklung Udjo | C7: =Matriks_Keputusan!C9 -> 75000 | D7: =Matriks_Keputusan!D9 -> 4.7 | E7: =Matriks_Keputusan!E9 -> 4.5624148 | F7: =Matriks_Keputusan!F9 -> 0.8 | G7: =Matriks_Keputusan!G9 -> 0.5 | H7: =Matriks_Keputusan!H9 -> 0.2
A8: =Matriks_Keputusan!A10 -> A4 | B8: =Matriks_Keputusan!B10 -> Farmhouse Lembang | C8: =Matriks_Keputusan!C10 -> 30000 | D8: =Matriks_Keputusan!D10 -> 4.3 | E8: =Matriks_Keputusan!E10 -> 9.5688101 | F8: =Matriks_Keputusan!F10 -> 0.8 | G8: =Matriks_Keputusan!G10 -> 0 | H8: =Matriks_Keputusan!H10 -> 0.5
A9: =Matriks_Keputusan!A11 -> A5 | B9: =Matriks_Keputusan!B11 -> Trans Studio Bandung | C9: =Matriks_Keputusan!C11 -> 200000 | D9: =Matriks_Keputusan!D11 -> 4.5 | E9: =Matriks_Keputusan!E11 -> 2.1408772 | F9: =Matriks_Keputusan!F11 -> 1 | G9: =Matriks_Keputusan!G11 -> 0 | H9: =Matriks_Keputusan!H11 -> 0.25
A10: =Matriks_Keputusan!A12 -> A6 | B10: =Matriks_Keputusan!B12 -> Pantai Pangandaran | C10: =Matriks_Keputusan!C12 -> 15000 | D10: =Matriks_Keputusan!D12 -> 4.2 | E10: =Matriks_Keputusan!E12 -> 143.27425 | F10: =Matriks_Keputusan!F12 -> 1 | G10: =Matriks_Keputusan!G12 -> 1 | H10: =Matriks_Keputusan!H12 -> 0.4
A11: =Matriks_Keputusan!A13 -> A7 | B11: =Matriks_Keputusan!B13 -> Museum Geologi Bandung | C11: =Matriks_Keputusan!C13 -> 5000 | D11: =Matriks_Keputusan!D13 -> 4.5 | E11: =Matriks_Keputusan!E13 -> 1.8867674 | F11: =Matriks_Keputusan!F13 -> 0.6 | G11: =Matriks_Keputusan!G13 -> 0.5 | H11: =Matriks_Keputusan!H13 -> 0
A12: =Matriks_Keputusan!A14 -> A8 | B12: =Matriks_Keputusan!B14 -> Dusun Bambu Lembang | C12: =Matriks_Keputusan!C14 -> 25000 | D12: =Matriks_Keputusan!D14 -> 4.4 | E12: =Matriks_Keputusan!E14 -> 14.36066 | F12: =Matriks_Keputusan!F14 -> 1 | G12: =Matriks_Keputusan!G14 -> 0 | H12: =Matriks_Keputusan!H14 -> 0.5
A13: =Matriks_Keputusan!A15 -> A9 | B13: =Matriks_Keputusan!B15 -> Situ Patenggang | C13: =Matriks_Keputusan!C15 -> 20000 | D13: =Matriks_Keputusan!D15 -> 4.3 | E13: =Matriks_Keputusan!E15 -> 39.685866 | F13: =Matriks_Keputusan!F15 -> 0.6 | G13: =Matriks_Keputusan!G15 -> 1 | H13: =Matriks_Keputusan!H15 -> 0.4
A14: =Matriks_Keputusan!A16 -> A10 | B14: =Matriks_Keputusan!B16 -> Masjid Raya Al Jabbar | C14: =Matriks_Keputusan!C16 -> 5000 | D14: =Matriks_Keputusan!D16 -> 4.1 | E14: =Matriks_Keputusan!E16 -> 8.4022857 | F14: =Matriks_Keputusan!F16 -> 0.8 | G14: =Matriks_Keputusan!G16 -> 0 | H14: =Matriks_Keputusan!H16 -> 0.2
A15: √Σ_i x_ij² | C15: =SQRT(SUMSQ(C5:C14)) -> 235129.75 | D15: =SQRT(SUMSQ(D5:D14)) -> 13.924798 | E15: =SQRT(SUMSQ(E5:E14)) -> 155.39138 | F15: =SQRT(SUMSQ(F5:F14)) -> 2.6305893 | G15: =SQRT(SUMSQ(G5:G14)) -> 2.1213203 | H15: =SQRT(SUMSQ(H5:H14)) -> 1.2093387
A17: Langkah 2 — Normalisasi vektor r_ij = x_ij ÷ √Σ_i x_ij²
A18: ID | B18: Destinasi | C18: C1 | D18: C2 | E18: C3 | F18: C4 | G18: C5 | H18: C6
A19: =A5 -> A1 | B19: =B5 -> Kawah Putih Ciwidey | C19: =C5/C$15 -> 0.34449065 | D19: =D5/D$15 -> 0.3303459 | E19: =E5/E$15 -> 0.23537044 | F19: =F5/F$15 -> 0.30411437 | G19: =G5/G$15 -> 0.47140452 | H19: =H5/H$15 -> 0.41344912
A20: =A6 -> A2 | B20: =B6 -> Gunung Tangkuban Perahu | C20: =C6/C$15 -> 0.12758913 | D20: =D6/D$15 -> 0.31598304 | E20: =E6/E$15 -> 0.11311582 | F20: =F6/F$15 -> 0.30411437 | G20: =G6/G$15 -> 0.47140452 | H20: =H6/H$15 -> 0.41344912
A21: =A7 -> A3 | B21: =B7 -> Saung Angklung Udjo | C21: =C7/C$15 -> 0.31897282 | D21: =D7/D$15 -> 0.33752734 | E21: =E7/E$15 -> 0.029360797 | F21: =F7/F$15 -> 0.30411437 | G21: =G7/G$15 -> 0.23570226 | H21: =H7/H$15 -> 0.16537965
A22: =A8 -> A4 | B22: =B8 -> Farmhouse Lembang | C22: =C8/C$15 -> 0.12758913 | D22: =D8/D$15 -> 0.30880161 | E22: =E8/E$15 -> 0.06157877 | F22: =F8/F$15 -> 0.30411437 | G22: =G8/G$15 -> 0 | H22: =H8/H$15 -> 0.41344912
A23: =A9 -> A5 | B23: =B9 -> Trans Studio Bandung | C23: =C9/C$15 -> 0.85059419 | D23: =D9/D$15 -> 0.32316447 | E23: =E9/E$15 -> 0.013777322 | F23: =F9/F$15 -> 0.38014296 | G23: =G9/G$15 -> 0 | H23: =H9/H$15 -> 0.20672456
A24: =A10 -> A6 | B24: =B10 -> Pantai Pangandaran | C24: =C10/C$15 -> 0.063794564 | D24: =D10/D$15 -> 0.30162017 | E24: =E10/E$15 -> 0.92202184 | F24: =F10/F$15 -> 0.38014296 | G24: =G10/G$15 -> 0.47140452 | H24: =H10/H$15 -> 0.33075929
A25: =A11 -> A7 | B25: =B11 -> Museum Geologi Bandung | C25: =C11/C$15 -> 0.021264855 | D25: =D11/D$15 -> 0.32316447 | E25: =E11/E$15 -> 0.012142034 | F25: =F11/F$15 -> 0.22808578 | G25: =G11/G$15 -> 0.23570226 | H25: =H11/H$15 -> 0
A26: =A12 -> A8 | B26: =B12 -> Dusun Bambu Lembang | C26: =C12/C$15 -> 0.10632427 | D26: =D12/D$15 -> 0.31598304 | E26: =E12/E$15 -> 0.092416063 | F26: =F12/F$15 -> 0.38014296 | G26: =G12/G$15 -> 0 | H26: =H12/H$15 -> 0.41344912
A27: =A13 -> A9 | B27: =B13 -> Situ Patenggang | C27: =C13/C$15 -> 0.085059419 | D27: =D13/D$15 -> 0.30880161 | E27: =E13/E$15 -> 0.25539297 | F27: =F13/F$15 -> 0.22808578 | G27: =G13/G$15 -> 0.47140452 | H27: =H13/H$15 -> 0.33075929
A28: =A14 -> A10 | B28: =B14 -> Masjid Raya Al Jabbar | C28: =C14/C$15 -> 0.021264855 | D28: =D14/D$15 -> 0.29443874 | E28: =E14/E$15 -> 0.054071761 | F28: =F14/F$15 -> 0.30411437 | G28: =G14/G$15 -> 0 | H28: =H14/H$15 -> 0.16537965
A30: Langkah 3 — Matriks ternormalisasi terbobot v_ij = w_j × r_ij
A31: Bobot w_j (AHP) | C31: =Matriks_Keputusan!C6 -> 0.26929411 | D31: =Matriks_Keputusan!D6 -> 0.17848215 | E31: =Matriks_Keputusan!E6 -> 0.15674302 | F31: =Matriks_Keputusan!F6 -> 0.081994696 | G31: =Matriks_Keputusan!G6 -> 0.15674302 | H31: =Matriks_Keputusan!H6 -> 0.15674302
A32: ID | B32: Destinasi | C32: C1 | D32: C2 | E32: C3 | F32: C4 | G32: C5 | H32: C6
A33: =A5 -> A1 | B33: =B5 -> Kawah Putih Ciwidey | C33: =C$31*C19 -> 0.092769303 | D33: =D$31*D19 -> 0.058960846 | E33: =E$31*E19 -> 0.036892673 | F33: =F$31*F19 -> 0.024935765 | G33: =G$31*G19 -> 0.073889366 | H33: =H$31*H19 -> 0.064805261
A34: =A6 -> A2 | B34: =B6 -> Gunung Tangkuban Perahu | C34: =C$31*C20 -> 0.034359001 | D34: =D$31*D20 -> 0.056397331 | E34: =E$31*E20 -> 0.017730114 | F34: =F$31*F20 -> 0.024935765 | G34: =G$31*G20 -> 0.073889366 | H34: =H$31*H20 -> 0.064805261
A35: =A7 -> A3 | B35: =B7 -> Saung Angklung Udjo | C35: =C$31*C21 -> 0.085897502 | D35: =D$31*D21 -> 0.060242603 | E35: =E$31*E21 -> 0.0046020999 | F35: =F$31*F21 -> 0.024935765 | G35: =G$31*G21 -> 0.036944683 | H35: =H$31*H21 -> 0.025922104
A36: =A8 -> A4 | B36: =B8 -> Farmhouse Lembang | C36: =C$31*C22 -> 0.034359001 | D36: =D$31*D22 -> 0.055115573 | E36: =E$31*E22 -> 0.0096520421 | F36: =F$31*F22 -> 0.024935765 | G36: =G$31*G22 -> 0 | H36: =H$31*H22 -> 0.064805261
A37: =A9 -> A5 | B37: =B9 -> Trans Studio Bandung | C37: =C$31*C23 -> 0.22906001 | D37: =D$31*D23 -> 0.057679088 | E37: =E$31*E23 -> 0.0021594991 | F37: =F$31*F23 -> 0.031169707 | G37: =G$31*G23 -> 0 | H37: =H$31*H23 -> 0.032402631
A38: =A10 -> A6 | B38: =B10 -> Pantai Pangandaran | C38: =C$31*C24 -> 0.0171795 | D38: =D$31*D24 -> 0.053833816 | E38: =E$31*E24 -> 0.14452048 | F38: =F$31*F24 -> 0.031169707 | G38: =G$31*G24 -> 0.073889366 | H38: =H$31*H24 -> 0.051844209
A39: =A11 -> A7 | B39: =B11 -> Museum Geologi Bandung | C39: =C$31*C25 -> 0.0057265002 | D39: =D$31*D25 -> 0.057679088 | E39: =E$31*E25 -> 0.001903179 | F39: =F$31*F25 -> 0.018701824 | G39: =G$31*G25 -> 0.036944683 | H39: =H$31*H25 -> 0
A40: =A12 -> A8 | B40: =B12 -> Dusun Bambu Lembang | C40: =C$31*C26 -> 0.028632501 | D40: =D$31*D26 -> 0.056397331 | E40: =E$31*E26 -> 0.014485572 | F40: =F$31*F26 -> 0.031169707 | G40: =G$31*G26 -> 0 | H40: =H$31*H26 -> 0.064805261
A41: =A13 -> A9 | B41: =B13 -> Situ Patenggang | C41: =C$31*C27 -> 0.022906001 | D41: =D$31*D27 -> 0.055115573 | E41: =E$31*E27 -> 0.040031064 | F41: =F$31*F27 -> 0.018701824 | G41: =G$31*G27 -> 0.073889366 | H41: =H$31*H27 -> 0.051844209
A42: =A14 -> A10 | B42: =B14 -> Masjid Raya Al Jabbar | C42: =C$31*C28 -> 0.0057265002 | D42: =D$31*D28 -> 0.052552058 | E42: =E$31*E28 -> 0.0084753709 | F42: =F$31*F28 -> 0.024935765 | G42: =G$31*G28 -> 0 | H42: =H$31*H28 -> 0.025922104
...

Sheet SAW_Pembanding
A1: 7. SAW (Simple Additive Weighting) — Pembanding untuk Validasi
A2: Bobot sama dengan TOPSIS. Hasil ini TIDAK dipakai sebagai rekomendasi; hanya untuk uji kesepakatan ranking (Spearman ρ).
A3: Jenis | C3: =Matriks_Keputusan!C5 -> Cost | D3: =Matriks_Keputusan!D5 -> Benefit | E3: =Matriks_Keputusan!E5 -> Cost | F3: =Matriks_Keputusan!F5 -> Benefit | G3: =Matriks_Keputusan!G5 -> Benefit | H3: =Matriks_Keputusan!H5 -> Benefit
A4: Bobot w_j | C4: =Matriks_Keputusan!C6 -> 0.26929411 | D4: =Matriks_Keputusan!D6 -> 0.17848215 | E4: =Matriks_Keputusan!E6 -> 0.15674302 | F4: =Matriks_Keputusan!F6 -> 0.081994696 | G4: =Matriks_Keputusan!G6 -> 0.15674302 | H4: =Matriks_Keputusan!H6 -> 0.15674302
A5: ID | B5: Destinasi | C5: C1 | D5: C2 | E5: C3 | F5: C4 | G5: C5 | H5: C6
A6: =Matriks_Keputusan!A7 -> A1 | B6: =Matriks_Keputusan!B7 -> Kawah Putih Ciwidey | C6: =Matriks_Keputusan!C7 -> 81000 | D6: =Matriks_Keputusan!D7 -> 4.6 | E6: =Matriks_Keputusan!E7 -> 36.574538 | F6: =Matriks_Keputusan!F7 -> 0.8 | G6: =Matriks_Keputusan!G7 -> 1 | H6: =Matriks_Keputusan!H7 -> 0.5
A7: =Matriks_Keputusan!A8 -> A2 | B7: =Matriks_Keputusan!B8 -> Gunung Tangkuban Perahu | C7: =Matriks_Keputusan!C8 -> 30000 | D7: =Matriks_Keputusan!D8 -> 4.4 | E7: =Matriks_Keputusan!E8 -> 17.577223 | F7: =Matriks_Keputusan!F8 -> 0.8 | G7: =Matriks_Keputusan!G8 -> 1 | H7: =Matriks_Keputusan!H8 -> 0.5
A8: =Matriks_Keputusan!A9 -> A3 | B8: =Matriks_Keputusan!B9 -> Saung Angklung Udjo | C8: =Matriks_Keputusan!C9 -> 75000 | D8: =Matriks_Keputusan!D9 -> 4.7 | E8: =Matriks_Keputusan!E9 -> 4.5624148 | F8: =Matriks_Keputusan!F9 -> 0.8 | G8: =Matriks_Keputusan!G9 -> 0.5 | H8: =Matriks_Keputusan!H9 -> 0.2
A9: =Matriks_Keputusan!A10 -> A4 | B9: =Matriks_Keputusan!B10 -> Farmhouse Lembang | C9: =Matriks_Keputusan!C10 -> 30000 | D9: =Matriks_Keputusan!D10 -> 4.3 | E9: =Matriks_Keputusan!E10 -> 9.5688101 | F9: =Matriks_Keputusan!F10 -> 0.8 | G9: =Matriks_Keputusan!G10 -> 0 | H9: =Matriks_Keputusan!H10 -> 0.5
A10: =Matriks_Keputusan!A11 -> A5 | B10: =Matriks_Keputusan!B11 -> Trans Studio Bandung | C10: =Matriks_Keputusan!C11 -> 200000 | D10: =Matriks_Keputusan!D11 -> 4.5 | E10: =Matriks_Keputusan!E11 -> 2.1408772 | F10: =Matriks_Keputusan!F11 -> 1 | G10: =Matriks_Keputusan!G11 -> 0 | H10: =Matriks_Keputusan!H11 -> 0.25
A11: =Matriks_Keputusan!A12 -> A6 | B11: =Matriks_Keputusan!B12 -> Pantai Pangandaran | C11: =Matriks_Keputusan!C12 -> 15000 | D11: =Matriks_Keputusan!D12 -> 4.2 | E11: =Matriks_Keputusan!E12 -> 143.27425 | F11: =Matriks_Keputusan!F12 -> 1 | G11: =Matriks_Keputusan!G12 -> 1 | H11: =Matriks_Keputusan!H12 -> 0.4
A12: =Matriks_Keputusan!A13 -> A7 | B12: =Matriks_Keputusan!B13 -> Museum Geologi Bandung | C12: =Matriks_Keputusan!C13 -> 5000 | D12: =Matriks_Keputusan!D13 -> 4.5 | E12: =Matriks_Keputusan!E13 -> 1.8867674 | F12: =Matriks_Keputusan!F13 -> 0.6 | G12: =Matriks_Keputusan!G13 -> 0.5 | H12: =Matriks_Keputusan!H13 -> 0
A13: =Matriks_Keputusan!A14 -> A8 | B13: =Matriks_Keputusan!B14 -> Dusun Bambu Lembang | C13: =Matriks_Keputusan!C14 -> 25000 | D13: =Matriks_Keputusan!D14 -> 4.4 | E13: =Matriks_Keputusan!E14 -> 14.36066 | F13: =Matriks_Keputusan!F14 -> 1 | G13: =Matriks_Keputusan!G14 -> 0 | H13: =Matriks_Keputusan!H14 -> 0.5
A14: =Matriks_Keputusan!A15 -> A9 | B14: =Matriks_Keputusan!B15 -> Situ Patenggang | C14: =Matriks_Keputusan!C15 -> 20000 | D14: =Matriks_Keputusan!D15 -> 4.3 | E14: =Matriks_Keputusan!E15 -> 39.685866 | F14: =Matriks_Keputusan!F15 -> 0.6 | G14: =Matriks_Keputusan!G15 -> 1 | H14: =Matriks_Keputusan!H15 -> 0.4
A15: =Matriks_Keputusan!A16 -> A10 | B15: =Matriks_Keputusan!B16 -> Masjid Raya Al Jabbar | C15: =Matriks_Keputusan!C16 -> 5000 | D15: =Matriks_Keputusan!D16 -> 4.1 | E15: =Matriks_Keputusan!E16 -> 8.4022857 | F15: =Matriks_Keputusan!F16 -> 0.8 | G15: =Matriks_Keputusan!G16 -> 0 | H15: =Matriks_Keputusan!H16 -> 0.2
A17: Normalisasi SAW: Benefit r_ij = x_ij ÷ max_j ; Cost r_ij = min_j ÷ x_ij
A18: ID | B18: Destinasi | C18: C1 | D18: C2 | E18: C3 | F18: C4 | G18: C5 | H18: C6
A19: =A6 -> A1 | B19: =B6 -> Kawah Putih Ciwidey | C19: =IF(C$3="Benefit",C6/MAX(C$6:C$15),MIN(C$6:C$15)/C6) -> 0.061728395 | D19: =IF(D$3="Benefit",D6/MAX(D$6:D$15),MIN(D$6:D$15)/D6) -> 0.9787234 | E19: =IF(E$3="Benefit",E6/MAX(E$6:E$15),MIN(E$6:E$15)/E6) -> 0.05158691 | F19: =IF(F$3="Benefit",F6/MAX(F$6:F$15),MIN(F$6:F$15)/F6) -> 0.8 | G19: =IF(G$3="Benefit",G6/MAX(G$6:G$15),MIN(G$6:G$15)/G6) -> 1 | H19: =IF(H$3="Benefit",H6/MAX(H$6:H$15),MIN(H$6:H$15)/H6) -> 1
A20: =A7 -> A2 | B20: =B7 -> Gunung Tangkuban Perahu | C20: =IF(C$3="Benefit",C7/MAX(C$6:C$15),MIN(C$6:C$15)/C7) -> 0.16666667 | D20: =IF(D$3="Benefit",D7/MAX(D$6:D$15),MIN(D$6:D$15)/D7) -> 0.93617021 | E20: =IF(E$3="Benefit",E7/MAX(E$6:E$15),MIN(E$6:E$15)/E7) -> 0.10734161 | F20: =IF(F$3="Benefit",F7/MAX(F$6:F$15),MIN(F$6:F$15)/F7) -> 0.8 | G20: =IF(G$3="Benefit",G7/MAX(G$6:G$15),MIN(G$6:G$15)/G7) -> 1 | H20: =IF(H$3="Benefit",H7/MAX(H$6:H$15),MIN(H$6:H$15)/H7) -> 1
A21: =A8 -> A3 | B21: =B8 -> Saung Angklung Udjo | C21: =IF(C$3="Benefit",C8/MAX(C$6:C$15),MIN(C$6:C$15)/C8) -> 0.066666667 | D21: =IF(D$3="Benefit",D8/MAX(D$6:D$15),MIN(D$6:D$15)/D8) -> 1 | E21: =IF(E$3="Benefit",E8/MAX(E$6:E$15),MIN(E$6:E$15)/E8) -> 0.41354578 | F21: =IF(F$3="Benefit",F8/MAX(F$6:F$15),MIN(F$6:F$15)/F8) -> 0.8 | G21: =IF(G$3="Benefit",G8/MAX(G$6:G$15),MIN(G$6:G$15)/G8) -> 0.5 | H21: =IF(H$3="Benefit",H8/MAX(H$6:H$15),MIN(H$6:H$15)/H8) -> 0.4
A22: =A9 -> A4 | B22: =B9 -> Farmhouse Lembang | C22: =IF(C$3="Benefit",C9/MAX(C$6:C$15),MIN(C$6:C$15)/C9) -> 0.16666667 | D22: =IF(D$3="Benefit",D9/MAX(D$6:D$15),MIN(D$6:D$15)/D9) -> 0.91489362 | E22: =IF(E$3="Benefit",E9/MAX(E$6:E$15),MIN(E$6:E$15)/E9) -> 0.19717889 | F22: =IF(F$3="Benefit",F9/MAX(F$6:F$15),MIN(F$6:F$15)/F9) -> 0.8 | G22: =IF(G$3="Benefit",G9/MAX(G$6:G$15),MIN(G$6:G$15)/G9) -> 0 | H22: =IF(H$3="Benefit",H9/MAX(H$6:H$15),MIN(H$6:H$15)/H9) -> 1
A23: =A10 -> A5 | B23: =B10 -> Trans Studio Bandung | C23: =IF(C$3="Benefit",C10/MAX(C$6:C$15),MIN(C$6:C$15)/C10) -> 0.025 | D23: =IF(D$3="Benefit",D10/MAX(D$6:D$15),MIN(D$6:D$15)/D10) -> 0.95744681 | E23: =IF(E$3="Benefit",E10/MAX(E$6:E$15),MIN(E$6:E$15)/E10) -> 0.88130577 | F23: =IF(F$3="Benefit",F10/MAX(F$6:F$15),MIN(F$6:F$15)/F10) -> 1 | G23: =IF(G$3="Benefit",G10/MAX(G$6:G$15),MIN(G$6:G$15)/G10) -> 0 | H23: =IF(H$3="Benefit",H10/MAX(H$6:H$15),MIN(H$6:H$15)/H10) -> 0.5
A24: =A11 -> A6 | B24: =B11 -> Pantai Pangandaran | C24: =IF(C$3="Benefit",C11/MAX(C$6:C$15),MIN(C$6:C$15)/C11) -> 0.33333333 | D24: =IF(D$3="Benefit",D11/MAX(D$6:D$15),MIN(D$6:D$15)/D11) -> 0.89361702 | E24: =IF(E$3="Benefit",E11/MAX(E$6:E$15),MIN(E$6:E$15)/E11) -> 0.013168922 | F24: =IF(F$3="Benefit",F11/MAX(F$6:F$15),MIN(F$6:F$15)/F11) -> 1 | G24: =IF(G$3="Benefit",G11/MAX(G$6:G$15),MIN(G$6:G$15)/G11) -> 1 | H24: =IF(H$3="Benefit",H11/MAX(H$6:H$15),MIN(H$6:H$15)/H11) -> 0.8
A25: =A12 -> A7 | B25: =B12 -> Museum Geologi Bandung | C25: =IF(C$3="Benefit",C12/MAX(C$6:C$15),MIN(C$6:C$15)/C12) -> 1 | D25: =IF(D$3="Benefit",D12/MAX(D$6:D$15),MIN(D$6:D$15)/D12) -> 0.95744681 | E25: =IF(E$3="Benefit",E12/MAX(E$6:E$15),MIN(E$6:E$15)/E12) -> 1 | F25: =IF(F$3="Benefit",F12/MAX(F$6:F$15),MIN(F$6:F$15)/F12) -> 0.6 | G25: =IF(G$3="Benefit",G12/MAX(G$6:G$15),MIN(G$6:G$15)/G12) -> 0.5 | H25: =IF(H$3="Benefit",H12/MAX(H$6:H$15),MIN(H$6:H$15)/H12) -> 0
A26: =A13 -> A8 | B26: =B13 -> Dusun Bambu Lembang | C26: =IF(C$3="Benefit",C13/MAX(C$6:C$15),MIN(C$6:C$15)/C13) -> 0.2 | D26: =IF(D$3="Benefit",D13/MAX(D$6:D$15),MIN(D$6:D$15)/D13) -> 0.93617021 | E26: =IF(E$3="Benefit",E13/MAX(E$6:E$15),MIN(E$6:E$15)/E13) -> 0.13138445 | F26: =IF(F$3="Benefit",F13/MAX(F$6:F$15),MIN(F$6:F$15)/F13) -> 1 | G26: =IF(G$3="Benefit",G13/MAX(G$6:G$15),MIN(G$6:G$15)/G13) -> 0 | H26: =IF(H$3="Benefit",H13/MAX(H$6:H$15),MIN(H$6:H$15)/H13) -> 1
A27: =A14 -> A9 | B27: =B14 -> Situ Patenggang | C27: =IF(C$3="Benefit",C14/MAX(C$6:C$15),MIN(C$6:C$15)/C14) -> 0.25 | D27: =IF(D$3="Benefit",D14/MAX(D$6:D$15),MIN(D$6:D$15)/D14) -> 0.91489362 | E27: =IF(E$3="Benefit",E14/MAX(E$6:E$15),MIN(E$6:E$15)/E14) -> 0.047542553 | F27: =IF(F$3="Benefit",F14/MAX(F$6:F$15),MIN(F$6:F$15)/F14) -> 0.6 | G27: =IF(G$3="Benefit",G14/MAX(G$6:G$15),MIN(G$6:G$15)/G14) -> 1 | H27: =IF(H$3="Benefit",H14/MAX(H$6:H$15),MIN(H$6:H$15)/H14) -> 0.8
A28: =A15 -> A10 | B28: =B15 -> Masjid Raya Al Jabbar | C28: =IF(C$3="Benefit",C15/MAX(C$6:C$15),MIN(C$6:C$15)/C15) -> 1 | D28: =IF(D$3="Benefit",D15/MAX(D$6:D$15),MIN(D$6:D$15)/D15) -> 0.87234043 | E28: =IF(E$3="Benefit",E15/MAX(E$6:E$15),MIN(E$6:E$15)/E15) -> 0.22455406 | F28: =IF(F$3="Benefit",F15/MAX(F$6:F$15),MIN(F$6:F$15)/F15) -> 0.8 | G28: =IF(G$3="Benefit",G15/MAX(G$6:G$15),MIN(G$6:G$15)/G15) -> 0 | H28: =IF(H$3="Benefit",H15/MAX(H$6:H$15),MIN(H$6:H$15)/H15) -> 0.4
A30: Skor SAW, peringkat, dan perbandingan dengan TOPSIS
A31: ID | B31: Destinasi | C31: S_i = Σ w_j·r_ij | D31: Peringkat SAW | E31: Peringkat TOPSIS | F31: d = r_TOPSIS − r_SAW | G31: d²
A32: =A6 -> A1 | B32: =B6 -> Kawah Putih Ciwidey | C32: =SUMPRODUCT(C19:H19,$C$4:$H$4) -> 0.57847542 | D32: =RANK(C32,$C$32:$C$41,0) -> 5 | E32: =INDEX(TOPSIS!$F$51:$F$60,MATCH(A32,TOPSIS!$A$51:$A$60,0)) -> 8 | F32: =E32-D32 -> 3 | G32: =F32^2 -> 9
A33: =A7 -> A2 | B33: =B7 -> Gunung Tangkuban Perahu | C33: =SUMPRODUCT(C20:H20,$C$4:$H$4) -> 0.60787886 | D33: =RANK(C33,$C$32:$C$41,0) -> 3 | E33: =INDEX(TOPSIS!$F$51:$F$60,MATCH(A33,TOPSIS!$A$51:$A$60,0)) -> 1 | F33: =E33-D33 -> -2 | G33: =F33^2 -> 4
A34: =A8 -> A3 | B34: =B8 -> Saung Angklung Udjo | C34: =SUMPRODUCT(C21:H21,$C$4:$H$4) -> 0.46791997 | D34: =RANK(C34,$C$32:$C$41,0) -> 9 | E34: =INDEX(TOPSIS!$F$51:$F$60,MATCH(A34,TOPSIS!$A$51:$A$60,0)) -> 7 | F34: =E34-D34 -> -2 | G34: =F34^2 -> 4
A35: =A9 -> A4 | B35: =B9 -> Farmhouse Lembang | C35: =SUMPRODUCT(C22:H22,$C$4:$H$4) -> 0.46141971 | D35: =RANK(C35,$C$32:$C$41,0) -> 10 | E35: =INDEX(TOPSIS!$F$51:$F$60,MATCH(A35,TOPSIS!$A$51:$A$60,0)) -> 6 | F35: =E35-D35 -> -4 | G35: =F35^2 -> 16
A36: =A10 -> A5 | B36: =B10 -> Trans Studio Bandung | C36: =SUMPRODUCT(C23:H23,$C$4:$H$4) -> 0.47612424 | D36: =RANK(C36,$C$32:$C$41,0) -> 8 | E36: =INDEX(TOPSIS!$F$51:$F$60,MATCH(A36,TOPSIS!$A$51:$A$60,0)) -> 10 | F36: =E36-D36 -> 2 | G36: =F36^2 -> 4
A37: =A11 -> A6 | B37: =B11 -> Pantai Pangandaran | C37: =SUMPRODUCT(C24:H24,$C$4:$H$4) -> 0.61545565 | D37: =RANK(C37,$C$32:$C$41,0) -> 2 | E37: =INDEX(TOPSIS!$F$51:$F$60,MATCH(A37,TOPSIS!$A$51:$A$60,0)) -> 9 | F37: =E37-D37 -> 7 | G37: =F37^2 -> 49
A38: =A12 -> A7 | B38: =B12 -> Museum Geologi Bandung | C38: =SUMPRODUCT(C25:H25,$C$4:$H$4) -> 0.72449261 | D38: =RANK(C38,$C$32:$C$41,0) -> 1 | E38: =INDEX(TOPSIS!$F$51:$F$60,MATCH(A38,TOPSIS!$A$51:$A$60,0)) -> 3 | F38: =E38-D38 -> 2 | G38: =F38^2 -> 4
A39: =A13 -> A8 | B39: =B13 -> Dusun Bambu Lembang | C39: =SUMPRODUCT(C26:H26,$C$4:$H$4) -> 0.4802798 | D39: =RANK(C39,$C$32:$C$41,0) -> 7 | E39: =INDEX(TOPSIS!$F$51:$F$60,MATCH(A39,TOPSIS!$A$51:$A$60,0)) -> 4 | F39: =E39-D39 -> -3 | G39: =F39^2 -> 9
A40: =A14 -> A9 | B40: =B14 -> Situ Patenggang | C40: =SUMPRODUCT(C27:H27,$C$4:$H$4) -> 0.56940191 | D40: =RANK(C40,$C$32:$C$41,0) -> 6 | E40: =INDEX(TOPSIS!$F$51:$F$60,MATCH(A40,TOPSIS!$A$51:$A$60,0)) -> 2 | F40: =E40-D40 -> -4 | G40: =F40^2 -> 16
A41: =A15 -> A10 | B41: =B15 -> Masjid Raya Al Jabbar | C41: =SUMPRODUCT(C28:H28,$C$4:$H$4) -> 0.58848155 | D41: =RANK(C41,$C$32:$C$41,0) -> 4 | E41: =INDEX(TOPSIS!$F$51:$F$60,MATCH(A41,TOPSIS!$A$51:$A$60,0)) -> 5 | F41: =E41-D41 -> 1 | G41: =F41^2 -> 1
A42: Σ d² | G42: =SUM(G32:G41) -> 116
...

Sheet Hasil
A1: 8. Hasil Akhir — Ranking Rekomendasi dan Alternatif Terbaik
A2: Tabel terurut otomatis dari peringkat TOPSIS (INDEX/MATCH). Tidak ada angka yang diketik manual.
A4: Profil pengguna
A5: Kota asal | B5: =Profil_User!$B$5 -> Bandung
A6: Budget maksimal | B6: =Profil_User!$B$8 -> 250000
A7: Wilayah | B7: =Profil_User!$B$9 -> Jawa Barat
A8: Kategori utama / sekunder | B8: =Profil_User!$B$10&" / "&Profil_User!$B$11 -> Alam / Budaya
A9: Profil prioritas (AHP) | B9: =Profil_User!$B$12 -> Seimbang
A10: CR AHP | B10: =AHP_Bobot!D38 -> 0.0084184201
A12: Peringkat | B12: ID | C12: Destinasi | D12: Kategori | E12: Harga (Rp) | F12: Rating | G12: Jarak (km) | H12: Vi (TOPSIS) | I12: Peringkat SAW
A13: 1 | B13: =INDEX(TOPSIS!$A$51:$A$60,MATCH(A13,TOPSIS!$F$51:$F$60,0)) -> A2 | C13: =INDEX(TOPSIS!$B$51:$B$60,MATCH(A13,TOPSIS!$F$51:$F$60,0)) -> Gunung Tangkuban Perahu | D13: =INDEX(Data_Alternatif!$D$6:$D$15,MATCH(B13,Data_Alternatif!$A$6:$A$15,0)) -> Alam | E13: =INDEX(Data_Alternatif!$E$6:$E$15,MATCH(B13,Data_Alternatif!$A$6:$A$15,0)) -> 30000 | F13: =INDEX(Data_Alternatif!$F$6:$F$15,MATCH(B13,Data_Alternatif!$A$6:$A$15,0)) -> 4.4 | G13: =INDEX(Data_Alternatif!$T$6:$T$15,MATCH(B13,Data_Alternatif!$A$6:$A$15,0)) -> 17.577223 | H13: =INDEX(TOPSIS!$E$51:$E$60,MATCH(A13,TOPSIS!$F$51:$F$60,0)) -> 0.8827405 | I13: =INDEX(SAW_Pembanding!$D$32:$D$41,MATCH(B13,SAW_Pembanding!$A$32:$A$41,0)) -> 3
A14: 2 | B14: =INDEX(TOPSIS!$A$51:$A$60,MATCH(A14,TOPSIS!$F$51:$F$60,0)) -> A9 | C14: =INDEX(TOPSIS!$B$51:$B$60,MATCH(A14,TOPSIS!$F$51:$F$60,0)) -> Situ Patenggang | D14: =INDEX(Data_Alternatif!$D$6:$D$15,MATCH(B14,Data_Alternatif!$A$6:$A$15,0)) -> Alam | E14: =INDEX(Data_Alternatif!$E$6:$E$15,MATCH(B14,Data_Alternatif!$A$6:$A$15,0)) -> 20000 | F14: =INDEX(Data_Alternatif!$F$6:$F$15,MATCH(B14,Data_Alternatif!$A$6:$A$15,0)) -> 4.3 | G14: =INDEX(Data_Alternatif!$T$6:$T$15,MATCH(B14,Data_Alternatif!$A$6:$A$15,0)) -> 39.685866 | H14: =INDEX(TOPSIS!$E$51:$E$60,MATCH(A14,TOPSIS!$F$51:$F$60,0)) -> 0.84415393 | I14: =INDEX(SAW_Pembanding!$D$32:$D$41,MATCH(B14,SAW_Pembanding!$A$32:$A$41,0)) -> 6
A15: 3 | B15: =INDEX(TOPSIS!$A$51:$A$60,MATCH(A15,TOPSIS!$F$51:$F$60,0)) -> A7 | C15: =INDEX(TOPSIS!$B$51:$B$60,MATCH(A15,TOPSIS!$F$51:$F$60,0)) -> Museum Geologi Bandung | D15: =INDEX(Data_Alternatif!$D$6:$D$15,MATCH(B15,Data_Alternatif!$A$6:$A$15,0)) -> Budaya | E15: =INDEX(Data_Alternatif!$E$6:$E$15,MATCH(B15,Data_Alternatif!$A$6:$A$15,0)) -> 5000 | F15: =INDEX(Data_Alternatif!$F$6:$F$15,MATCH(B15,Data_Alternatif!$A$6:$A$15,0)) -> 4.5 | G15: =INDEX(Data_Alternatif!$T$6:$T$15,MATCH(B15,Data_Alternatif!$A$6:$A$15,0)) -> 1.8867674 | H15: =INDEX(TOPSIS!$E$51:$E$60,MATCH(A15,TOPSIS!$F$51:$F$60,0)) -> 0.77954952 | I15: =INDEX(SAW_Pembanding!$D$32:$D$41,MATCH(B15,SAW_Pembanding!$A$32:$A$41,0)) -> 1
A16: 4 | B16: =INDEX(TOPSIS!$A$51:$A$60,MATCH(A16,TOPSIS!$F$51:$F$60,0)) -> A8 | C16: =INDEX(TOPSIS!$B$51:$B$60,MATCH(A16,TOPSIS!$F$51:$F$60,0)) -> Dusun Bambu Lembang | D16: =INDEX(Data_Alternatif!$D$6:$D$15,MATCH(B16,Data_Alternatif!$A$6:$A$15,0)) -> Kuliner | E16: =INDEX(Data_Alternatif!$E$6:$E$15,MATCH(B16,Data_Alternatif!$A$6:$A$15,0)) -> 25000 | F16: =INDEX(Data_Alternatif!$F$6:$F$15,MATCH(B16,Data_Alternatif!$A$6:$A$15,0)) -> 4.4 | G16: =INDEX(Data_Alternatif!$T$6:$T$15,MATCH(B16,Data_Alternatif!$A$6:$A$15,0)) -> 14.36066 | H16: =INDEX(TOPSIS!$E$51:$E$60,MATCH(A16,TOPSIS!$F$51:$F$60,0)) -> 0.75956284 | I16: =INDEX(SAW_Pembanding!$D$32:$D$41,MATCH(B16,SAW_Pembanding!$A$32:$A$41,0)) -> 7
A17: 5 | B17: =INDEX(TOPSIS!$A$51:$A$60,MATCH(A17,TOPSIS!$F$51:$F$60,0)) -> A10 | C17: =INDEX(TOPSIS!$B$51:$B$60,MATCH(A17,TOPSIS!$F$51:$F$60,0)) -> Masjid Raya Al Jabbar | D17: =INDEX(Data_Alternatif!$D$6:$D$15,MATCH(B17,Data_Alternatif!$A$6:$A$15,0)) -> Religi | E17: =INDEX(Data_Alternatif!$E$6:$E$15,MATCH(B17,Data_Alternatif!$A$6:$A$15,0)) -> 5000 | F17: =INDEX(Data_Alternatif!$F$6:$F$15,MATCH(B17,Data_Alternatif!$A$6:$A$15,0)) -> 4.1 | G17: =INDEX(Data_Alternatif!$T$6:$T$15,MATCH(B17,Data_Alternatif!$A$6:$A$15,0)) -> 8.4022857 | H17: =INDEX(TOPSIS!$E$51:$E$60,MATCH(A17,TOPSIS!$F$51:$F$60,0)) -> 0.75709376 | I17: =INDEX(SAW_Pembanding!$D$32:$D$41,MATCH(B17,SAW_Pembanding!$A$32:$A$41,0)) -> 4
A18: 6 | B18: =INDEX(TOPSIS!$A$51:$A$60,MATCH(A18,TOPSIS!$F$51:$F$60,0)) -> A4 | C18: =INDEX(TOPSIS!$B$51:$B$60,MATCH(A18,TOPSIS!$F$51:$F$60,0)) -> Farmhouse Lembang | D18: =INDEX(Data_Alternatif!$D$6:$D$15,MATCH(B18,Data_Alternatif!$A$6:$A$15,0)) -> Hiburan | E18: =INDEX(Data_Alternatif!$E$6:$E$15,MATCH(B18,Data_Alternatif!$A$6:$A$15,0)) -> 30000 | F18: =INDEX(Data_Alternatif!$F$6:$F$15,MATCH(B18,Data_Alternatif!$A$6:$A$15,0)) -> 4.3 | G18: =INDEX(Data_Alternatif!$T$6:$T$15,MATCH(B18,Data_Alternatif!$A$6:$A$15,0)) -> 9.5688101 | H18: =INDEX(TOPSIS!$E$51:$E$60,MATCH(A18,TOPSIS!$F$51:$F$60,0)) -> 0.75426894 | I18: =INDEX(SAW_Pembanding!$D$32:$D$41,MATCH(B18,SAW_Pembanding!$A$32:$A$41,0)) -> 10
A19: 7 | B19: =INDEX(TOPSIS!$A$51:$A$60,MATCH(A19,TOPSIS!$F$51:$F$60,0)) -> A3 | C19: =INDEX(TOPSIS!$B$51:$B$60,MATCH(A19,TOPSIS!$F$51:$F$60,0)) -> Saung Angklung Udjo | D19: =INDEX(Data_Alternatif!$D$6:$D$15,MATCH(B19,Data_Alternatif!$A$6:$A$15,0)) -> Budaya | E19: =INDEX(Data_Alternatif!$E$6:$E$15,MATCH(B19,Data_Alternatif!$A$6:$A$15,0)) -> 75000 | F19: =INDEX(Data_Alternatif!$F$6:$F$15,MATCH(B19,Data_Alternatif!$A$6:$A$15,0)) -> 4.7 | G19: =INDEX(Data_Alternatif!$T$6:$T$15,MATCH(B19,Data_Alternatif!$A$6:$A$15,0)) -> 4.5624148 | H19: =INDEX(TOPSIS!$E$51:$E$60,MATCH(A19,TOPSIS!$F$51:$F$60,0)) -> 0.67996102 | I19: =INDEX(SAW_Pembanding!$D$32:$D$41,MATCH(B19,SAW_Pembanding!$A$32:$A$41,0)) -> 9
A20: 8 | B20: =INDEX(TOPSIS!$A$51:$A$60,MATCH(A20,TOPSIS!$F$51:$F$60,0)) -> A1 | C20: =INDEX(TOPSIS!$B$51:$B$60,MATCH(A20,TOPSIS!$F$51:$F$60,0)) -> Kawah Putih Ciwidey | D20: =INDEX(Data_Alternatif!$D$6:$D$15,MATCH(B20,Data_Alternatif!$A$6:$A$15,0)) -> Alam | E20: =INDEX(Data_Alternatif!$E$6:$E$15,MATCH(B20,Data_Alternatif!$A$6:$A$15,0)) -> 81000 | F20: =INDEX(Data_Alternatif!$F$6:$F$15,MATCH(B20,Data_Alternatif!$A$6:$A$15,0)) -> 4.6 | G20: =INDEX(Data_Alternatif!$T$6:$T$15,MATCH(B20,Data_Alternatif!$A$6:$A$15,0)) -> 36.574538 | H20: =INDEX(TOPSIS!$E$51:$E$60,MATCH(A20,TOPSIS!$F$51:$F$60,0)) -> 0.67993066 | I20: =INDEX(SAW_Pembanding!$D$32:$D$41,MATCH(B20,SAW_Pembanding!$A$32:$A$41,0)) -> 5
A21: 9 | B21: =INDEX(TOPSIS!$A$51:$A$60,MATCH(A21,TOPSIS!$F$51:$F$60,0)) -> A6 | C21: =INDEX(TOPSIS!$B$51:$B$60,MATCH(A21,TOPSIS!$F$51:$F$60,0)) -> Pantai Pangandaran | D21: =INDEX(Data_Alternatif!$D$6:$D$15,MATCH(B21,Data_Alternatif!$A$6:$A$15,0)) -> Alam | E21: =INDEX(Data_Alternatif!$E$6:$E$15,MATCH(B21,Data_Alternatif!$A$6:$A$15,0)) -> 15000 | F21: =INDEX(Data_Alternatif!$F$6:$F$15,MATCH(B21,Data_Alternatif!$A$6:$A$15,0)) -> 4.2 | G21: =INDEX(Data_Alternatif!$T$6:$T$15,MATCH(B21,Data_Alternatif!$A$6:$A$15,0)) -> 143.27425 | H21: =INDEX(TOPSIS!$E$51:$E$60,MATCH(A21,TOPSIS!$F$51:$F$60,0)) -> 0.61595819 | I21: =INDEX(SAW_Pembanding!$D$32:$D$41,MATCH(B21,SAW_Pembanding!$A$32:$A$41,0)) -> 2
A22: 10 | B22: =INDEX(TOPSIS!$A$51:$A$60,MATCH(A22,TOPSIS!$F$51:$F$60,0)) -> A5 | C22: =INDEX(TOPSIS!$B$51:$B$60,MATCH(A22,TOPSIS!$F$51:$F$60,0)) -> Trans Studio Bandung | D22: =INDEX(Data_Alternatif!$D$6:$D$15,MATCH(B22,Data_Alternatif!$A$6:$A$15,0)) -> Hiburan | E22: =INDEX(Data_Alternatif!$E$6:$E$15,MATCH(B22,Data_Alternatif!$A$6:$A$15,0)) -> 200000 | F22: =INDEX(Data_Alternatif!$F$6:$F$15,MATCH(B22,Data_Alternatif!$A$6:$A$15,0)) -> 4.5 | G22: =INDEX(Data_Alternatif!$T$6:$T$15,MATCH(B22,Data_Alternatif!$A$6:$A$15,0)) -> 2.1408772 | H22: =INDEX(TOPSIS!$E$51:$E$60,MATCH(A22,TOPSIS!$F$51:$F$60,0)) -> 0.38173402 | I22: =INDEX(SAW_Pembanding!$D$32:$D$41,MATCH(B22,SAW_Pembanding!$A$32:$A$41,0)) -> 8
A25: ALTERNATIF TERBAIK
A26: Destinasi | B26: =C13 -> Gunung Tangkuban Perahu
A27: Nilai preferensi Vi | B27: =H13 -> 0.8827405
A28: Kalimat rekomendasi | B28: ="Rekomendasi utama: "&C13&" (Vi = "&ROUND(H13,4)&"), disusul "&C14&" (Vi = "&ROUND(H14,4)&") dan "&C15&" (Vi = "&ROUND(H15,4)&")." -> Rekomendasi utama: Gunung Tangkuban Perahu (Vi = 0,8827), disusul Situ Patenggang (Vi = 0,8442) dan Museum Geologi Bandung (Vi = 0,7795).
A30: Alasan rekomendasi — kedekatan alternatif terbaik ke solusi ideal per kriteria (dari TOPSIS Langkah 6)
A31: Kriteria | B31: Nama | C31: Jenis | D31: Nilai x | E31: Kedekatan c | F31: Penilaian
A32: C1 | B32: Harga Tiket (Rp) | C32: =Kriteria!$C$5 -> Cost | D32: =INDEX(Matriks_Keputusan!$C$7:$C$16,MATCH($B$13,Matriks_Keputusan!$A$7:$A$16,0)) -> 30000 | E32: =INDEX(TOPSIS!$C$66:$C$75,MATCH($B$13,TOPSIS!$A$66:$A$75,0)) -> 0.87179487 | F32: =IF(E32>=0.8,"Unggul",IF(E32>=0.5,"Cukup","Lemah")) -> Unggul
A33: C2 | B33: Rating Pengunjung | C33: =Kriteria!$C$6 -> Benefit | D33: =INDEX(Matriks_Keputusan!$D$7:$D$16,MATCH($B$13,Matriks_Keputusan!$A$7:$A$16,0)) -> 4.4 | E33: =INDEX(TOPSIS!$D$66:$D$75,MATCH($B$13,TOPSIS!$A$66:$A$75,0)) -> 0.5 | F33: =IF(E33>=0.8,"Unggul",IF(E33>=0.5,"Cukup","Lemah")) -> Cukup
A34: C3 | B34: Jarak (km) | C34: =Kriteria!$C$7 -> Cost | D34: =INDEX(Matriks_Keputusan!$E$7:$E$16,MATCH($B$13,Matriks_Keputusan!$A$7:$A$16,0)) -> 17.577223 | E34: =INDEX(TOPSIS!$E$66:$E$75,MATCH($B$13,TOPSIS!$A$66:$A$75,0)) -> 0.88902514 | F34: =IF(E34>=0.8,"Unggul",IF(E34>=0.5,"Cukup","Lemah")) -> Unggul
A35: C4 | B35: Skor Fasilitas | C35: =Kriteria!$C$8 -> Benefit | D35: =INDEX(Matriks_Keputusan!$F$7:$F$16,MATCH($B$13,Matriks_Keputusan!$A$7:$A$16,0)) -> 0.8 | E35: =INDEX(TOPSIS!$F$66:$F$75,MATCH($B$13,TOPSIS!$A$66:$A$75,0)) -> 0.5 | F35: =IF(E35>=0.8,"Unggul",IF(E35>=0.5,"Cukup","Lemah")) -> Cukup
A36: C5 | B36: Skor Kategori | C36: =Kriteria!$C$9 -> Benefit | D36: =INDEX(Matriks_Keputusan!$G$7:$G$16,MATCH($B$13,Matriks_Keputusan!$A$7:$A$16,0)) -> 1 | E36: =INDEX(TOPSIS!$G$66:$G$75,MATCH($B$13,TOPSIS!$A$66:$A$75,0)) -> 1 | F36: =IF(E36>=0.8,"Unggul",IF(E36>=0.5,"Cukup","Lemah")) -> Unggul
A37: C6 | B37: Skor Hobi (Jaccard) | C37: =Kriteria!$C$10 -> Benefit | D37: =INDEX(Matriks_Keputusan!$H$7:$H$16,MATCH($B$13,Matriks_Keputusan!$A$7:$A$16,0)) -> 0.5 | E37: =INDEX(TOPSIS!$H$66:$H$75,MATCH($B$13,TOPSIS!$A$66:$A$75,0)) -> 1 | F37: =IF(E37>=0.8,"Unggul",IF(E37>=0.5,"Cukup","Lemah")) -> Unggul
A39: Cara membaca: 'Unggul' berarti nilai terbobot destinasi ini hampir sama dengan solusi ideal pada kriteria tersebut; 'Lemah' berarti kriteria ini yang menahan skornya. Inilah dasar kalimat penjelasan di aplikasi (mis. 'direkomendasikan karena harga sesuai budget dan cocok dengan minat alam, namun jaraknya cukup jauh').
